2019-07-20 19:14:10,325 [INFO ]  Starting Rasa server on http://localhost:5005
2019-07-20 19:14:50,786 [ERROR]  Task was destroyed but it is pending!
task: <Task pending coro=<configure_app.<locals>.run_cmdline_io() running at /Users/bhavani/virtualenv/chatbot_tutorial/lib/python3.7/site-packages/rasa/core/run.py:119> wait_for=<Future pending cb=[<TaskWakeupMethWrapper object at 0x13338e1c8>()]>>
2019-07-20 19:16:32,208 [INFO ]  Starting Rasa server on http://localhost:5005
2019-07-20 19:20:12,316 [ERROR]  Task was destroyed but it is pending!
task: <Task pending coro=<configure_app.<locals>.run_cmdline_io() running at /Users/bhavani/virtualenv/chatbot_tutorial/lib/python3.7/site-packages/rasa/core/run.py:119> wait_for=<Future pending cb=[<TaskWakeupMethWrapper object at 0x12efbffa8>()]>>
2019-07-20 19:20:25,244 [INFO ]  Starting Rasa server on http://localhost:5005
2019-07-20 19:20:59,310 [ERROR]  Task was destroyed but it is pending!
task: <Task pending coro=<configure_app.<locals>.run_cmdline_io() running at /Users/bhavani/virtualenv/chatbot_tutorial/lib/python3.7/site-packages/rasa/core/run.py:119> wait_for=<Future pending cb=[<TaskWakeupMethWrapper object at 0x12d1d7768>()]>>
2019-07-20 19:24:48,035 [INFO ]  Starting Rasa server on http://localhost:5005
2019-07-20 19:27:22,678 [ERROR]  Encountered an exception while running action 'action_default_fallback'. Bot will continue, but the actions events are lost. Make sure to fix the exception in your custom code.
2019-07-20 19:30:02,561 [INFO ]  Killing Sanic server now.
2019-07-20 19:30:12,270 [INFO ]  Starting Rasa server on http://localhost:5005
2019-07-20 19:30:23,672 [INFO ]  Killing Sanic server now.
2019-07-20 19:31:27,129 [INFO ]  Starting Rasa server on http://localhost:5005
2019-07-20 19:31:27,142 [WARNI]  No local NLU model '/var/folders/q1/tpsgz0nn60l0z6t2hrh6z1zm0000gn/T/tmpqadplw7l/nlu' found. Using RegexInterpreter instead.
2019-07-20 19:34:34,937 [ERROR]  Failed to run custom action 'action_default_fallback'. Couldn't connect to the server at 'http://localhost:5055/webhook'. Is the server running? Error: Cannot connect to host localhost:5055 ssl:None [Connection refused]
2019-07-20 19:34:34,938 [ERROR]  Encountered an exception while running action 'action_default_fallback'. Bot will continue, but the actions events are lost. Make sure to fix the exception in your custom code.
